<robot name="dynamixel">
  <link name="base_link" />		#NEEDS TO HAVE THIS NAME OMG HAVE I SPENT A WHOLE DAY TO FIND OUT
  <link name="platform" />
  <link name="lower_arm" />
  <link name="middle_arm" />
  <link name="upper_arm" />
  <link name="pre_wrist" />
  <link name="wrist" />
  <link name="post_wrist" />
  <link name="tip" />

  <joint name="rotating_base" type="continuous">
    <parent link="base_link"/>
    <child link="platform"/>
    <origin xyz="0 0 6" rpy="0 0 0" />
    <axis xyz="0 0 1" />
  </joint>

  <joint name="lower_arm_actuator" type="revolute">
    <parent link="platform"/>
    <child link="lower_arm"/>
    <origin xyz="0 0 5.5" rpy="0 0 0" />
    <axis xyz="0 1 0" />
    <limit lower="-2.35619449019" upper="0" />		# -75 deg to 0 deg
  </joint>

  <joint name="middle_arm_actuator" type="revolute">
    <parent link="lower_arm"/>
    <child link="middle_arm"/>
    <origin xyz="16 0 0" rpy="0 0 0" />
    <axis xyz="0 1 0" />
    <limit lower="0" upper="1.91986" />		# 0 deg to 110 deg
  </joint>

  <joint name="upper_arm_actuator" type="revolute">
    <parent link="middle_arm"/>
    <child link="upper_arm"/>
    <origin xyz="9 0 0" rpy="0 0 0" />
    <axis xyz="0 1 0" />
    <limit lower="-1.91986" upper="1.91986" />  # - 110 deg to 110 deg
																
  </joint>

  <joint name="pre_wrist" type="revolute">
    <parent link="upper_arm"/>
    <child link="pre_wrist"/>
    <origin xyz="0 0 1" rpy="0 0 0" />
    <axis xyz="0 0 0" />
    <limit lower="0" upper="0" />  	# cannot rotate
  </joint>

  <joint name="wrist" type="revolute">
    <parent link="pre_wrist"/>
    <child link="wrist"/>
    <origin xyz="9 0 0" rpy="0 0 0" />
    <axis xyz="1 0 0" />
    <limit lower="-3.13" upper="3.13" />  	# - 180 deg to 180 deg (a little less)
  </joint>

  <joint name="post_wrist" type="revolute">
    <parent link="wrist"/>
    <child link="post_wrist"/>
    <origin xyz="0 0 1.5" rpy="0 0 0" />
    <axis xyz="0 0 0" />
    <limit lower="0" upper="0" />  	# cannot rotate
  </joint>

  <joint name="grippers" type="revolute">
    <parent link="post_wrist"/>
    <child link="tip"/>
    <origin xyz="16 0 0" rpy="0 0 0" />
    <axis xyz="0 0 0" />
    <limit lower="0" upper="0" />  	# cannot rotate
  </joint>

</robot>
